<?xml version="1.0"?>
<robot name="cart">
		
<link name="base_link">
    <visual>
      <geometry>
        <cylinder length="2.0" radius="2.0"/>
      </geometry>
      <collision>
      <geometry>
        <cylinder length="2.0" radius="2.0"/>
      </geometry>
    </collision>
    </visual>
  </link>
  
  <link name="link">
    <visual>
      <geometry>
        <cylinder length="1.0" radius="1.0"/>
      </geometry>
      <origin rpy="1 2 3" xyz="0 0 0"/>
      <collision>
      <geometry>
        <cylinder length="1.0" radius="1.0"/>
      </geometry>
      <origin rpy="1 2 3" xyz="0 0 0"/>
    </collision>
    </visual>
  </link>
  
  
  <joint name="base_first_" type="continuous">
    <axis rpy="0 0 0" xyz="0 0 1"/>
    <parent link="base_link"/>
    <child link="link"/>
    <origin xyz="0.0 0.0 2.0"/>
  </joint>
</robot>
